Workbook
Name Car_AM: 'Bowen Tce'!$B$37
Name Car_EV: 'Bowen Tce'!$E$37
Name Car_OP: 'Bowen Tce'!$C$37
Name Car_PM: 'Bowen Tce'!$D$37
Name D1_Row: 'Bowen Tce'!$B$34
Name D2_Row: 'Bowen Tce'!$C$34
Name Direction: 'Bowen Tce'!$B$44
Name HCV_AM: 'Bowen Tce'!$B$39
Name HCV_EV: 'Bowen Tce'!$E$39
Name HCV_OP: 'Bowen Tce'!$C$39
Name HCV_PM: 'Bowen Tce'!$D$39
Name Latitude: 'Bowen Tce'!$B$45
Name Location: 'Bowen Tce'!$B$43
Name Longitude: 'Bowen Tce'!$B$46
Name MCV_AM: 'Bowen Tce'!$B$38
Name MCV_EV: 'Bowen Tce'!$E$38
Name MCV_OP: 'Bowen Tce'!$C$38
Name MCV_PM: 'Bowen Tce'!$D$38
Name Road_Name: 'Bowen Tce'!$B$42

Sheet Traffic Count
A1: _id | B1: SL | C1: point | D1: Description | E1: STUDY AREA | F1: Dir | G1: name | H1: Location | I1: Direct. | J1: X | K1: Y | L1: 2012 Obs. AM Car | M1: 2012 Obs. AM MCV | N1: 2012 Obs. AM HCV | O1: 2012 Obs. AM Total | P1: 2012 Obs. OP Car | Q1: 2012 Obs. OP MCV | R1: 2012 Obs. OP HCV | S1: 2012 Obs. OP Total | T1: 2012 Obs. PM Car | U1: 2012 Obs. PM MCV | V1: 2012 Obs. PM HCV | W1: 2012 Obs. PM Total | X1: 2012 Obs. EV Car | Y1: 2012 Obs. EV MCV | Z1: 2012 Obs. EV HCV | AA1: 2012 Obs. EV Total | AB1: 2012 Obs. WD Car | AC1: 2012 Obs. WD MCV | AD1: 2012 Obs. WD HCV | AE1: 2012 Obs. WD Total | AF1: 2013 Obs. WD Total
A2: 1 | B2: 9 | C2: 9.01 | D2: North of Caboolture | E2: BSTM | F2: Dir1 | G2: Bruce Hwy | H2: 400m North of Steve Irwin Way | I2: Southbound | J2: -26.980859 | K2: 152.981164 | L2: 3169 | M2: 257 | N2: 152 | O2: 3580 | P2: 8563 | Q2: 903 | R2: 512 | S2: 9979 | T2: 2597 | U2: 173 | V2: 144 | W2: 2914 | X2: 5506 | Y2: 508 | Z2: 482 | AA2: 6497 | AB2: 19835 | AC2: 1841 | AD2: 1290 | AE2: 22970
A3: 2 | B3: 9 | C3: 9.02 | D3: North of Caboolture | E3: BSTM | F3: Dir1 | G3: Steve Irwin Highway | H3: 600m South of Beerburrum Road | I3: Southbound | J3: -26.961857 | K3: 152.960255 | L3: 528 | M3: 40 | N3: 17 | O3: 585 | P3: 1226 | Q3: 123 | R3: 60 | S3: 1409 | T3: 406 | U3: 30 | V3: 8 | W3: 444 | X3: 869 | Y3: 88 | Z3: 46 | AA3: 1003 | AB3: 3029 | AC3: 281 | AD3: 131 | AE3: 3441
A4: 3 | B4: 9 | C4: 9.03 | D4: North of Caboolture | E4: BSTM | F4: Dir1 | G4: Beerburrum Road | H4: 500m South of Beerburrum - Woodford Road | I4: Southbound | J4: -26.963747 | K4: 152.953076 | L4: 250 | M4: 13 | N4: 1 | O4: 264 | P4: 565 | Q4: 47 | R4: 4 | S4: 616 | T4: 182 | U4: 9 | V4: 1 | W4: 192 | X4: 255 | Y4: 19 | Z4: 2 | AA4: 276 | AB4: 1252 | AC4: 88 | AD4: 8 | AE4: 1348
A5: 4 | B5: 9 | C5: 9.04 | D5: North of Caboolture | E5: BSTM | F5: Dir1 | G5: Old Gympie Rd | H5: 250m North of Beerburrum Woodford Rd | I5: Southbound | J5: -26.947288 | K5: 152.918129 | L5: 63 | M5: 2 | N5: 0 | O5: 65 | P5: 109 | Q5: 4 | R5: 2 | S5: 115 | T5: 32 | U5: 1 | V5: 0 | W5: 33 | X5: 66 | Y5: 0 | Z5: 0 | AA5: 66 | AB5: 270 | AC5: 7 | AD5: 2 | AE5: 279
A6: 5 | B6: 9 | C6: 9.05 | D6: North of Caboolture | E6: BSTM | F6: Dir1 | G6: D'Aguilar Hwy | H6: 500m North of Mount Mee Road | I6: Southbound | J6: -26.984503 | K6: 152.7957 | L6: 689 | M6: 32 | N6: 18 | O6: 739 | P6: 2000 | Q6: 152 | R6: 93 | S6: 2245 | T6: 622 | U6: 30 | V6: 18 | W6: 668 | X6: 1001 | Y6: 40 | Z6: 35 | AA6: 1076 | AB6: 4312 | AC6: 254 | AD6: 162 | AE6: 4728
A7: 6 | B7: 9 | C7: 9.06 | D7: North of Caboolture | E7: BSTM | F7: Dir1 | G7: Mt Mee - Woodford Rd | H7: 250m North of Robinsons Road | I7: Southbound | J7: -27.048216 | K7: 152.771577 | L7: 26 | M7: 3 | N7: 0 | O7: 29 | P7: 138 | Q7: 16 | R7: 2 | S7: 156 | T7: 49 | U7: 4 | V7: 0 | W7: 53 | X7: 64 | Y7: 6 | Z7: 1 | AA7: 71 | AB7: 277 | AC7: 29 | AD7: 3 | AE7: 309
A8: 7 | B8: 9 | C8: 9.01 | D8: North of Caboolture | E8: BSTM | F8: Dir2 | G8: Bruce Hwy | H8: 400m North of Steve Irwin Way | I8: Northbound | J8: -26.980859 | K8: 152.981164 | L8: 2564 | M8: 271 | N8: 136 | O8: 2971 | P8: 9159 | Q8: 927 | R8: 604 | S8: 10697 | T8: 3432 | U8: 203 | V8: 120 | W8: 3755 | X8: 4660 | Y8: 439 | Z8: 580 | AA8: 5680 | AB8: 19815 | AC8: 1840 | AD8: 1440 | AE8: 23103
A9: 8 | B9: 9 | C9: 9.02 | D9: North of Caboolture | E9: BSTM | F9: Dir2 | G9: Steve Irwin Highway | H9: 600m South of Beerburrum Road | I9: Northbound | J9: -26.961857 | K9: 152.960255 | L9: 328 | M9: 37 | N9: 19 | O9: 384 | P9: 1441 | Q9: 118 | R9: 62 | S9: 1621 | T9: 631 | U9: 27 | V9: 11 | W9: 669 | X9: 715 | Y9: 39 | Z9: 34 | AA9: 788 | AB9: 3115 | AC9: 221 | AD9: 126 | AE9: 3462
A10: 9 | B10: 9 | C10: 9.03 | D10: North of Caboolture | E10: BSTM | F10: Dir2 | G10: Beerburrum Road | H10: 500m South of Beerburrum - Woodford Road | I10: Northbound | J10: -26.963747 | K10: 152.953076 | L10: 138 | M10: 16 | N10: 2 | O10: 156 | P10: 634 | Q10: 40 | R10: 3 | S10: 677 | T10: 247 | U10: 7 | V10: 0 | W10: 254 | X10: 249 | Y10: 18 | Z10: 3 | AA10: 270 | AB10: 1268 | AC10: 81 | AD10: 8 | AE10: 1357
A11: 10 | B11: 9 | C11: 9.04 | D11: North of Caboolture | E11: BSTM | F11: Dir2 | G11: Old Gympie Rd | H11: 250m North of Beerburrum Woodford Rd | I11: Northbound | J11: -26.947288 | K11: 152.918129 | L11: 17 | M11: 1 | N11: 0 | O11: 18 | P11: 109 | Q11: 9 | R11: 1 | S11: 119 | T11: 48 | U11: 0 | V11: 0 | W11: 48 | X11: 48 | Y11: 0 | Z11: 0 | AA11: 48 | AB11: 222 | AC11: 10 | AD11: 1 | AE11: 233
A12: 11 | B12: 9 | C12: 9.05 | D12: North of Caboolture | E12: BSTM | F12: Dir2 | G12: D'Aguilar Hwy | H12: 500m North of Mount Mee Road | I12: Northbound | J12: -26.984503 | K12: 152.7957 | L12: 621 | M12: 73 | N12: 21 | O12: 715 | P12: 1852 | Q12: 202 | R12: 85 | S12: 2139 | T12: 723 | U12: 51 | V12: 16 | W12: 790 | X12: 916 | Y12: 85 | Z12: 50 | AA12: 1051 | AB12: 4112 | AC12: 411 | AD12: 172 | AE12: 4695
A13: 12 | B13: 9 | C13: 9.06 | D13: North of Caboolture | E13: BSTM | F13: Dir2 | G13: Mt Mee - Woodford Rd | H13: 250m North of Robinsons Road | I13: Northbound | J13: -27.048216 | K13: 152.771577 | L13: 46 | M13: 2 | N13: 0 | O13: 48 | P13: 144 | Q13: 9 | R13: 1 | S13: 154 | T13: 33 | U13: 2 | V13: 2 | W13: 37 | X13: 51 | Y13: 4 | Z13: 0 | AA13: 55 | AB13: 274 | AC13: 17 | AD13: 3 | AE13: 294
... A82: 81 | B82: 15 | C82: 15.03 | D82: Kedron Brook | E82: BSTM | F82: Dir1 | G82: Nudgee Road | H82: Kedron Brook at Shulz Canal | I82: Southbound | J82: -27.406876 | K82: 153.074151 | L82: 972 | M82: 68 | N82: 22 | O82: 1062 | P82: 2237 | Q82: 278 | R82: 101 | S82: 2616 | T82: 754 | U82: 27 | V82: 5 | W82: 786 | X82: 1340 | Y82: 127 | Z82: 23 | AA82: 1491 | AB82: 5303 | AC82: 500 | AD82: 151 | AE82: 5955
A83: 82 | B83: 15 | C83: 15.04 | D83: Kedron Brook | E83: BSTM | F83: Dir1 | G83: Widdop Road | H83: Kedron Brook at Shulz Canal | I83: Southbound | J83: -27.409833 | K83: 153.063755 | L83: 1456 | M83: 31 | N83: 2 | O83: 1489 | P83: 2536 | Q83: 80 | R83: 0 | S83: 2617 | T83: 969 | U83: 16 | V83: 0 | W83: 985 | X83: 1520 | Y83: 36 | Z83: 0 | AA83: 1556 | AB83: 6481 | AC83: 163 | AD83: 2 | AE83: 6647 | AF83: NB | AI83: =_05651c5a_c82e_48f6_9e7c_8df516722191[[#This Row],[2012 Obs. WD Total]]+AE102 -> 15033 | AJ83: =_05651c5a_c82e_48f6_9e7c_8df516722191[[#This Row],[2012 Obs. WD Total]]*100/AI83 -> 44.216058
A84: 83 | B84: 15 | C84: 15.05 | D84: Kedron Brook | E84: BSTM | F84: Dir1 | G84: Sandgate Sub-Arterial | H84: Kedron Brook | I84: Southbound | J84: -27.410476 | K84: 153.05927 | L84: 4638 | M84: 236 | N84: 12 | O84: 4886 | P84: 9807 | Q84: 716 | R84: 49 | S84: 10572 | T84: 2739 | U84: 106 | V84: 5 | W84: 2850 | X84: 8291 | Y84: 360 | Z84: 18 | AA84: 8669 | AB84: 25475 | AC84: 1418 | AD84: 84 | AE84: 26977
A85: 84 | B85: 15 | C85: 15.06 | D85: Kedron Brook | E85: BSTM | F85: Dir1 | G85: Shaw Road | H85: Kedron Brook | I85: Southbound | J85: -27.403623 | K85: 153.047705 | L85: 2763 | M85: 35 | N85: 4 | O85: 2802 | P85: 2830 | Q85: 85 | R85: 4 | S85: 2919 | T85: 1076 | U85: 8 | V85: 0 | W85: 1084 | X85: 2334 | Y85: 46 | Z85: 1 | AA85: 2381 | AB85: 9003 | AC85: 174 | AD85: 9 | AE85: 9186
A86: 85 | B86: 15 | C86: 15.07 | D86: Kedron Brook | E86: BSTM | F86: Dir1 | G86: Gympie Rd prior Airport Link | H86: Kedron Brook - Bridge Outbound | I86: Southbound | J86: -27.4143 | K86: 153.035071 | L86: 4618 | M86: 229 | N86: 33 | O86: 4880 | P86: 11069 | Q86: 817 | R86: 124 | S86: 12010 | T86: 3280 | U86: 153 | V86: 15 | W86: 3448 | X86: 9639 | Y86: 489 | Z86: 80 | AA86: 10208 | AB86: 28606 | AC86: 1688 | AD86: 252 | AE86: 30546
A87: 86 | B87: 15 | C87: 15.07a | D87: Kedron Brook | E87: BSTM | F87: Dir1 | G87: Gympie Rd at grade | H87: Kedron Brook - Bridge Inbound | I87: Southbound | J87: - | K87: - | L87: - | M87: - | N87: - | O87: - | P87: - | Q87: - | R87: - | S87: - | T87: - | U87: - | V87: - | W87: - | X87: - | Y87: - | Z87: - | AA87: - | AB87: - | AC87: - | AD87: - | AE87: - | AI87: =COLUMN(L83) -> 12
A88: 87 | B88: 15 | C88: 15.07b | D88: Kedron Brook | E88: BSTM | F88: Dir1 | G88: Gympie Rd - Motorway | H88: Kedron Brook - Bridge Inbound | I88: Southbound | J88: - | K88: - | L88: - | M88: - | N88: - | O88: - | P88: - | Q88: - | R88: - | S88: - | T88: - | U88: - | V88: - | W88: - | X88: - | Y88: - | Z88: - | AA88: - | AB88: - | AC88: - | AD88: - | AE88: -
A89: 88 | B89: 15 | C89: 15.08 | D89: Kedron Brook | E89: BSTM | F89: Dir1 | G89: Bradshaw Street | H89: Kedron Brook | I89: Southbound | J89: -27.420156 | K89: 153.032889 | L89: 1019 | M89: 26 | N89: 2 | O89: 1047 | P89: 1066 | Q89: 58 | R89: 3 | S89: 1127 | T89: 362 | U89: 12 | V89: 0 | W89: 374 | X89: 903 | Y89: 37 | Z89: 0 | AA89: 940 | AB89: 3350 | AC89: 133 | AD89: 5 | AE89: 3488
A90: 89 | B90: 15 | C90: 15.09 | D90: Kedron Brook | E90: BSTM | F90: Dir1 | G90: Gilbert Road | H90: Kedron Brook | I90: Southbound | J90: -27.421719 | K90: 153.024187 | L90: 1257 | M90: 15 | N90: 1 | O90: 1274 | P90: 724 | Q90: 17 | R90: 0 | S90: 741 | T90: 318 | U90: 4 | V90: 0 | W90: 322 | X90: 486 | Y90: 4 | Z90: 0 | AA90: 490 | AB90: 2785 | AC90: 40 | AD90: 1 | AE90: 2827
A91: 90 | B91: 15 | C91: 15.1 | D91: Kedron Brook | E91: BSTM | F91: Dir1 | G91: Webster Road | H91: Kedron Brook | I91: Southbound | J91: -27.419567 | K91: 153.01511 | L91: 2851 | M91: 104 | N91: 18 | O91: 2984 | P91: 5340 | Q91: 322 | R91: 11 | S91: 5676 | T91: 1905 | U91: 57 | V91: 0 | W91: 1962 | X91: 3759 | Y91: 165 | Z91: 9 | AA91: 3948 | AB91: 13855 | AC91: 648 | AD91: 38 | AE91: 14570
A92: 91 | B92: 15 | C92: 15.11 | D92: Kedron Brook | E92: BSTM | F92: Dir1 | G92: Shand Street | H92: Kedron Brook | I92: Southbound | J92: -27.415662 | K92: 153.001099 | L92: 2117 | M92: 135 | N92: 19 | O92: 2289 | P92: 5084 | Q92: 403 | R92: 38 | S92: 5525 | T92: 1667 | U92: 89 | V92: 3 | W92: 1759 | X92: 4100 | Y92: 230 | Z92: 8 | AA92: 4343 | AB92: 12968 | AC92: 857 | AD92: 68 | AE92: 13916
A93: 92 | B93: 15 | C93: 15.12 | D93: Kedron Brook | E93: BSTM | F93: Dir1 | G93: South Pine Road | H93: Kedron Brook | I93: Southbound | J93: -27.412291 | K93: 152.99228 | L93: 2328 | M93: 128 | N93: 29 | O93: 2499 | P93: 6580 | Q93: 576 | R93: 73 | S93: 7230 | T93: 1988 | U93: 123 | V93: 16 | W93: 2127 | X93: 5844 | Y93: 436 | Z93: 51 | AA93: 6369 | AB93: 16740 | AC93: 1263 | AD93: 169 | AE93: 18225
A94: 93 | B94: 15 | C94: 15.13 | D94: Kedron Brook | E94: BSTM | F94: Dir1 | G94: Burwood Road | H94: Kedron Brook | I94: Southbound | J94: -27.4084 | K94: 152.982699 | L94: 523 | M94: 25 | N94: 2 | O94: 550 | P94: 2525 | Q94: 99 | R94: 2 | S94: 2626 | T94: 691 | U94: 17 | V94: 0 | W94: 708 | X94: 738 | Y94: 18 | Z94: 0 | AA94: 756 | AB94: 4477 | AC94: 159 | AD94: 4 | AE94: 4640
A95: 94 | B95: 15 | C95: 15.14 | D95: Kedron Brook | E95: BSTM | F95: Dir1 | G95: Osborne Road | H95: Kedron Brook | I95: Southbound | J95: -27.40309 | K95: 152.978997 | L95: 2484 | M95: 43 | N95: 5 | O95: 2532 | P95: 3659 | Q95: 98 | R95: 3 | S95: 3760 | T95: 1130 | U95: 20 | V95: 0 | W95: 1150 | X95: 2183 | Y95: 39 | Z95: 2 | AA95: 2224 | AB95: 9456 | AC95: 200 | AD95: 10 | AE95: 9666
A96: 95 | B96: 15 | C96: 15.15 | D96: Kedron Brook | E96: BSTM | F96: Dir1 | G96: Dawson Pde | H96: Kedron Brook | I96: Southbound | J96: -27.399671 | K96: 152.961143 | L96: 2037 | M96: 46 | N96: 14 | O96: 2132 | P96: 4025 | Q96: 147 | R96: 17 | S96: 4189 | T96: 1469 | U96: 25 | V96: 2 | W96: 1496 | X96: 2946 | Y96: 68 | Z96: 5 | AA96: 3036 | AB96: 10477 | AC96: 286 | AD96: 38 | AE96: 10853
A97: 96 | B97: 15 | C97: 15.16 | D97: Kedron Brook | E97: BSTM | F97: Dir1 | G97: Samford Sub-Arterial Road | H97: South-east of Tramway Street | I97: Southbound | J97: -27.408177 | K97: 152.941064 | L97: 3039 | M97: 101 | N97: 10 | O97: 3173 | P97: 4119 | Q97: 252 | R97: 29 | S97: 4401 | T97: 1179 | U97: 54 | V97: 4 | W97: 1237 | X97: 2949 | Y97: 189 | Z97: 25 | AA97: 3190 | AB97: 11286 | AC97: 596 | AD97: 68 | AE97: 12001
A98: 97 | B98: 15 | C98: 15.17 | D98: Kedron Brook | E98: BSTM | F98: Dir1 | G98: Upper Kedron Road | H98: West of Samford Road | I98: Southbound | J98: -27.412659 | K98: 152.940729 | L98: 840 | M98: 33 | N98: 1 | O98: 903 | P98: 1121 | Q98: 87 | R98: 3 | S98: 1214 | T98: 370 | U98: 19 | V98: 1 | W98: 390 | X98: 780 | Y98: 40 | Z98: 1 | AA98: 822 | AB98: 3111 | AC98: 179 | AD98: 6 | AE98: 3329
A99: 98 | B99: 15 | C99: 15.01 | D99: Kedron Brook | E99: BSTM | F99: Dir2 | G99: Gateway Arterial | H99: Kedron Brook Floodway | I99: Northbound | J99: -27.394688 | K99: 153.093302 | L99: 2845 | M99: 329 | N99: 241 | O99: 3416 | P99: 9290 | Q99: 1180 | R99: 897 | S99: 11378 | T99: 2532 | U99: 217 | V99: 95 | W99: 2858 | X99: 6227 | Y99: 530 | Z99: 533 | AA99: 7292 | AB99: 20894 | AC99: 2256 | AD99: 1766 | AE99: 24944
... A101: 100 | B101: 15 | C101: 15.03 | D101: Kedron Brook | E101: BSTM | F101: Dir2 | G101: Nudgee Road | H101: Kedron Brook at Shulz Canal | I101: Northbound | J101: -27.406876 | K101: 153.074151 | L101: 636 | M101: 79 | N101: 20 | O101: 735 | P101: 2381 | Q101: 395 | R101: 101 | S101: 2877 | T101: 1589 | U101: 61 | V101: 14 | W101: 1664 | X101: 1137 | Y101: 67 | Z101: 15 | AA101: 1219 | AB101: 5743 | AC101: 602 | AD101: 150 | AE101: 6495
A102: 101 | B102: 15 | C102: 15.04 | D102: Kedron Brook | E102: BSTM | F102: Dir2 | G102: Widdop Road | H102: Kedron Brook at Shulz Canal | I102: Northbound | J102: -27.409833 | K102: 153.063755 | L102: 817 | M102: 33 | N102: 1 | O102: 851 | P102: 3372 | Q102: 121 | R102: 1 | S102: 3494 | T102: 1854 | U102: 43 | V102: 1 | W102: 1898 | X102: 2072 | Y102: 66 | Z102: 5 | AA102: 2143 | AB102: 8115 | AC102: 263 | AD102: 8 | AE102: 8386 | AF102: SB
A103: 102 | B103: 15 | C103: 15.05 | D103: Kedron Brook | E103: BSTM | F103: Dir2 | G103: Sandgate Sub-Arterial | H103: Kedron Brook | I103: Northbound | J103: -27.410476 | K103: 153.05927 | L103: 2416 | M103: 193 | N103: 15 | O103: 2624 | P103: 10381 | Q103: 770 | R103: 58 | S103: 11209 | T103: 4391 | U103: 120 | V103: 15 | W103: 4526 | X103: 6954 | Y103: 239 | Z103: 19 | AA103: 7212 | AB103: 24142 | AC103: 1322 | AD103: 107 | AE103: 25571
A104: 103 | B104: 15 | C104: 15.06 | D104: Kedron Brook | E104: BSTM | F104: Dir2 | G104: Shaw Road | H104: Kedron Brook | I104: Northbound | J104: -27.403623 | K104: 153.047705 | L104: 952 | M104: 32 | N104: 0 | O104: 984 | P104: 3603 | Q104: 121 | R104: 3 | S104: 3727 | T104: 2844 | U104: 53 | V104: 2 | W104: 2899 | X104: 2402 | Y104: 38 | Z104: 3 | AA104: 2443 | AB104: 9801 | AC104: 244 | AD104: 8 | AE104: 10053
A105: 104 | B105: 15 | C105: 15.07 | D105: Kedron Brook | E105: BSTM | F105: Dir2 | G105: Gympie Rd | H105: Kedron Brook - Bridge Outbound | I105: Northbound | J105: -27.4143 | K105: 153.035071 | L105: 3100 | M105: 253 | N105: 32 | O105: 3385 | P105: 13481 | Q105: 1003 | R105: 141 | S105: 14625 | T105: 5414 | U105: 161 | V105: 20 | W105: 5595 | X105: 9195 | Y105: 462 | Z105: 75 | AA105: 9732 | AB105: 31190 | AC105: 1879 | AD105: 268 | AE105: 33337
A106: 105 | B106: 15 | C106: 15.07a | D106: Kedron Brook | E106: BSTM | F106: Dir2 | G106: Gympie Rd at grade | H106: Kedron Brook - Bridge Inbound | I106: Southbound | J106: - | K106: - | L106: - | M106: - | N106: - | O106: - | P106: - | Q106: - | R106: - | S106: - | T106: - | U106: - | V106: - | W106: - | X106: - | Y106: - | Z106: - | AA106: - | AB106: - | AC106: - | AD106: - | AE106: -
A107: 106 | B107: 15 | C107: 15.07b | D107: Kedron Brook | E107: BSTM | F107: Dir2 | G107: Gympie Rd -Airpot Links | H107: Kedron Brook - Bridge Inbound | I107: Southbound | J107: - | K107: - | L107: - | M107: - | N107: - | O107: - | P107: - | Q107: - | R107: - | S107: - | T107: - | U107: - | V107: - | W107: - | X107: - | Y107: - | Z107: - | AA107: - | AB107: - | AC107: - | AD107: - | AE107: -
A108: 107 | B108: 15 | C108: 15.08 | D108: Kedron Brook | E108: BSTM | F108: Dir2 | G108: Bradshaw Street | H108: Kedron Brook | I108: Northbound | J108: -27.420156 | K108: 153.032889 | L108: 255 | M108: 17 | N108: 0 | O108: 272 | P108: 1271 | Q108: 86 | R108: 3 | S108: 1360 | T108: 929 | U108: 27 | V108: 0 | W108: 956 | X108: 1031 | Y108: 47 | Z108: 0 | AA108: 1078 | AB108: 3486 | AC108: 177 | AD108: 3 | AE108: 3666
A109: 108 | B109: 15 | C109: 15.09 | D109: Kedron Brook | E109: BSTM | F109: Dir2 | G109: Gilbert Road | H109: Kedron Brook | I109: Northbound | J109: -27.421719 | K109: 153.024187 | L109: 183 | M109: 4 | N109: 0 | O109: 187 | P109: 804 | Q109: 21 | R109: 0 | S109: 825 | T109: 979 | U109: 12 | V109: 0 | W109: 991 | X109: 536 | Y109: 8 | Z109: 0 | AA109: 544 | AB109: 2502 | AC109: 45 | AD109: 0 | AE109: 2547
...

Sheet Bowen Tce
A1: Data Source: https://www.data.qld.gov.au/dataset/brisbane-strategic-transport-demand-model-screenline-validation-data/resource/05651c5a-c82e-48f6-9e7c-8df516722191
J5: Hrs | N5: Count Location:
A6: Percent traffic assumed* | E6: AM | F6: 7 | G6: to | H6: 9 | J6: =H6-F6 -> 2 | N6: Dir 1 | O6: {=INDIRECT("'Traffic Count'!"&ADDRESS(D1_Row,Direction)) & ": " & INDIRECT("'Traffic Count'!"&ADDRESS(D1_Row,Road_Name)) & " at " & INDIRECT("'Traffic Count'!"&ADDRESS(D1_Row,Location)) & ". " & $A$45 & ": " & INDIRECT("'Traffic Count'!"&ADDRESS(D1_Row,Latitude)) & ", " & $A$46 & ": " & INDIRECT("'Traffic Count'!"&ADDRESS(D1_Row,Longitude))} -> Southbound: Lutwyche Rd at south of Nicolas St. Latitude: -27.44146, Longitude: 153.03037
A7: 20 | E7: OP | F7: 9 | G7: to | H7: 16 | J7: =H7-F7 -> 7 | N7: Dir 2 | O7: {=INDIRECT("'Traffic Count'!"&ADDRESS(D2_Row,Direction)) & ": " & INDIRECT("'Traffic Count'!"&ADDRESS(D2_Row,Road_Name)) & " at " & INDIRECT("'Traffic Count'!"&ADDRESS(D2_Row,Location)) & ". " & $A$45 & ": " & INDIRECT("'Traffic Count'!"&ADDRESS(D2_Row,Latitude)) & ", " & $A$46 & ": " & INDIRECT("'Traffic Count'!"&ADDRESS(D2_Row,Longitude))} -> Northbound: Lutwyche Rd at south of Nicolas St. Latitude: -27.44146, Longitude: 153.03037
E8: PM | F8: 16 | G8: to | H8: 18 | J8: =H8-F8 -> 2
A9: *100% if using the same counts | E9: EV | F9: 18 | G9: to | H9: 7 | J9: =24-F9+H9 -> 13 | N9: Is count location and road being assessed the same? | S9: No | AB9: {=IF($S$9="Yes", INDIRECT("'Traffic Count'!"&ADDRESS(D2_Row,Direction)) & ": " & INDIRECT("'Traffic Count'!"&ADDRESS(D2_Row,Road_Name)),(IF($S$11="Yes", INDIRECT("'Traffic Count'!"&ADDRESS(D2_Row,Direction)) & ": " & $S$10, $B$101 & ": " & $S$10)))} -> Eastbound: Norman Ave
N10: If no, what road is the analysis for? | S10: Norman Ave
B11: ID | E11: Year of Traffic Count | I11: Current year | N11: Is the direction of the road same | S11: No
A12: Dir 1 | B12: 169 | E12: 2012 | I12: =YEAR(TODAY()) -> 2026 | N12: Percentage of traffic assumed | S12: 5 | T12: {="% of "&INDIRECT("'Traffic Count'!"&ADDRESS(D1_Row,Road_Name))&" assumed for "&S10} -> % of Lutwyche Rd assumed for Norman Ave
A13: Dir 2 | B13: 187 | E13: Number of years | G13: =I12-E12 -> 14
E14: Growth Rate | G14: 2.5
N15: {=IF($S$9="Yes", "Queue Length Estimation: " & INDIRECT("'Traffic Count'!"&ADDRESS(D1_Row,Direction)) & ": " & INDIRECT("'Traffic Count'!"&ADDRESS(D1_Row,Road_Name)),(IF($S$11="Yes", "Queue Length Estimation: " & INDIRECT("'Traffic Count'!"&ADDRESS(D1_Row,Direction)) & ": " & $S$10, "Queue Length Estimation: " & $B$101 & ": " & $S$10)))} -> Queue Length Estimation: Eastbound: Norman Ave
N16: AM | Q16: OP | T16: PM | W16: EV | Z16: Total | AB16: =S10 & " - Traffic Impact Analysis" -> Norman Ave - Traffic Impact Analysis | AI16: LOS A (x<=0.6)
N17: Car | O17: MCV | P17: HCV | Q17: Car | R17: MCV | S17: HCV | T17: Car | U17: MCV | V17: HCV | W17: Car | X17: MCV | Y17: HCV | AC17: =IF(AB20="Eastbound", "EB", "NB") -> EB | AD17: =IF(AB21="Westbound", "WB", "SB") -> WB | AE17: Both Directions | AI17: LOS B (0.6 < x <= 0.7)
M18: =$E$12 -> 2012 | N18: {=INDIRECT("'Traffic Count'!"&ADDRESS(D1_Row,Car_AM))*$A$7%} -> 870.4 | O18: {=INDIRECT("'Traffic Count'!"&ADDRESS(D1_Row,MCV_AM))*$A$7%} -> 20.4 | P18: {=INDIRECT("'Traffic Count'!"&ADDRESS(D1_Row,HCV_AM))*$A$7%} -> 2 | Q18: {=INDIRECT("'Traffic Count'!"&ADDRESS(D1_Row,Car_OP))*$A$7%} -> 1667.6 | R18: {=INDIRECT("'Traffic Count'!"&ADDRESS(D1_Row,MCV_OP))*$A$7%} -> 71.8 | S18: {=INDIRECT("'Traffic Count'!"&ADDRESS(D1_Row,HCV_OP))*$A$7%} -> 6.8 | T18: {=INDIRECT("'Traffic Count'!"&ADDRESS(D1_Row,Car_PM))*$A$7%} -> 419.6 | U18: {=INDIRECT("'Traffic Count'!"&ADDRESS(D1_Row,MCV_PM))*$A$7%} -> 10.8 | V18: {=INDIRECT("'Traffic Count'!"&ADDRESS(D1_Row,HCV_PM))*$A$7%} -> 0.2 | W18: {=INDIRECT("'Traffic Count'!"&ADDRESS(D1_Row,Car_EV))*$A$7%} -> 1300 | X18: {=INDIRECT("'Traffic Count'!"&ADDRESS(D1_Row,MCV_EV))*$A$7%} -> 53.8 | Y18: {=INDIRECT("'Traffic Count'!"&ADDRESS(D1_Row,HCV_EV))*$A$7%} -> 7.2 | Z18: =N18+O18+P18+Q18+R18+S18+T18+U18+V18+W18+X18+Y18 -> 4430.6 | AB18: Design Volume (Capacity) * | AC18: =IF(ROUNDUP(0.12*Z19,0)<=500, 500,ROUNDUP(0.12*Z19,0)) -> 752 | AD18: =IF(ROUNDUP(0.12*Z34,0)<=500, 500,ROUNDUP(0.12*Z34,0)) -> 1251 | AE18: =MAX(AC18:AD18) -> 1251 | AI18: LOS C (0.7 < x <= 0.9)
L19: Estimated | M19: =$I$12 -> 2026 | N19: =ROUNDUP(N18*(1+$G$14/100)^$G$13,0) -> 1230 | O19: =ROUNDUP(O18*(1+$G$14/100)^$G$13,0) -> 29 | P19: =ROUNDUP(P18*(1+$G$14/100)^$G$13,0) -> 3 | Q19: =ROUNDUP(Q18*(1+$G$14/100)^$G$13,0) -> 2357 | R19: =ROUNDUP(R18*(1+$G$14/100)^$G$13,0) -> 102 | S19: =ROUNDUP(S18*(1+$G$14/100)^$G$13,0) -> 10 | T19: =ROUNDUP(T18*(1+$G$14/100)^$G$13,0) -> 593 | U19: =ROUNDUP(U18*(1+$G$14/100)^$G$13,0) -> 16 | ... Z19: =ROUNDUP(Z18*(1+$G$14/100)^$G$13,0) -> 6261 | AB19: VCR (Volume to Capacity Ratio) | AC19: AM | AD19: OP | AE19: PM | AF19: EV | AI19: LOS D (0.9 < x <= 0.95)
B20: Queue Length factors | M20: Hrly Avg | N20: =ROUNDUP(N19/$J$6,0) -> 615 | O20: =ROUNDUP(O19/$J$6,0) -> 15 | P20: =ROUNDUP(P19/$J$6,0) -> 2 | Q20: =ROUNDUP(Q19/$J$7,0) -> 337 | R20: =ROUNDUP(R19/$J$7,0) -> 15 | S20: =ROUNDUP(S19/$J$7,0) -> 2 | T20: =ROUNDUP(T19/$J$8,0) -> 297 | U20: =ROUNDUP(U19/$J$8,0) -> 8 | V20: =ROUNDUP(V19/$J$8,0) -> 1 | W20: =ROUNDUP(W19/$J$9,0) -> 142 | X20: =ROUNDUP(X19/$J$9,0) -> 6 | Y20: =ROUNDUP(Y19/$J$9,0) -> 1 | AB20: {=IF($S$11="Yes", INDIRECT("'Traffic Count'!"&ADDRESS(D1_Row,Direction)), $B$101)} -> Eastbound | AC20: =SUM(N20:P20)/AC18 -> 0.84042553 | AD20: =SUM(Q20:S20)/AC18 -> 0.47074468 | AE20: =SUM(T20:V20)/AC18 -> 0.40691489 | AF20: =SUM(W20:Y20)/AC18 -> 0.1981383 | AI20: LOS E (0.95 < x <= 1)
B21: Maximum stopping time (minutes) | C21: Multiplier | L21: Queue Length Estimation | AB21: {=IF($S$11="Yes", INDIRECT("'Traffic Count'!"&ADDRESS(D2_Row,Direction)), $B$102)} -> Westbound | AC21: =SUM(N20:P20)/AD18 -> 0.50519584 | AD21: =SUM(Q35:S35)/AD18 -> 0.50279776 | AE21: =SUM(T35:V35)/AD18 -> 0.74260592 | AF21: =SUM(W35:Y35)/AD18 -> 0.19184652 | AI21: LOS F ( 1 < x)
C22: Ma | D22: Mo | L22: Volume | M22: per 5 mins | N22: =ROUNDUP(N20*5/60,0) -> 52 | O22: =ROUNDUP(O20*5/60,0) -> 2 | P22: =ROUNDUP(P20*5/60,0) -> 1 | Q22: =ROUNDUP(Q20*5/60,0) -> 29 | R22: =ROUNDUP(R20*5/60,0) -> 2 | S22: =ROUNDUP(S20*5/60,0) -> 1 | T22: =ROUNDUP(T20*5/60,0) -> 25 | U22: =ROUNDUP(U20*5/60,0) -> 1 | ... Y22: =ROUNDUP(Y20*5/60,0) -> 1 | Z22: Max Queue | AB22: Single Lane Reversible Flow | AC22: =SUM(N20:P20,N35:P35)/AE18 -> 0.93045564 | AD22: =SUM(Q20:S20,Q35:S35)/AE18 -> 0.78577138 | AE22: =SUM(T35:V35,T20:V20)/AE18 -> 0.98721023 | AF22: =SUM(W20:Y20,W35:Y35)/AE18 -> 0.31095124
B23: 2 | C23: 2.4 | D23: 8 | L23: 2 min. | M23: Length (m) | N23: =N22*$C$23+(SUM(O22:P22)*$D$23) -> 148.8 | Q23: =Q22*$C$23+(SUM(R22:S22)*$D$23) -> 93.6 | T23: =T22*$C$23+(SUM(U22:V22)*$D$23) -> 76 | W23: =W22*$C$23+(SUM(X22:Y22)*$D$23) -> 44.8 | Z23: =MAX(N23:Y23) -> 148.8
B24: 5 | C24: 6 | D24: 20 | L24: 5 min. | M24: Length (m) | N24: =N22*$C$24+(SUM(O22:P22)*$D$24) -> 372 | Q24: =Q22*$C$24+(SUM(R22:S22)*$D$24) -> 234 | T24: =T22*$C$24+(SUM(U22:V22)*$D$24) -> 190 | W24: =W22*$C$24+(SUM(X22:Y22)*$D$24) -> 112 | Z24: =MAX(N24:Y24) -> 372 | AB24: * Greater of 30th Highest Hour of AADT or 500
B25: 10 | C25: 12 | D25: 40 | L25: 10 min. | M25: Length (m) | N25: =N22*$C$25+(SUM(O22:P22)*$D$25) -> 744 | Q25: =Q22*$C$25+(SUM(R22:S22)*$D$25) -> 468 | T25: =T22*$C$25+(SUM(U22:V22)*$D$25) -> 380 | W25: =W22*$C$25+(SUM(X22:Y22)*$D$25) -> 224 | Z25: =MAX(N25:Y25) -> 744
B26: 15 | C26: 18 | D26: 60
B27: 30 | C27: 36 | D27: 120
N30: {=IF($S$9="Yes", "Queue Length Estimation: " & INDIRECT("'Traffic Count'!"&ADDRESS(D2_Row,Direction)) & ": " & INDIRECT("'Traffic Count'!"&ADDRESS(D2_Row,Road_Name)),(IF($S$11="Yes", "Queue Length Estimation: " & INDIRECT("'Traffic Count'!"&ADDRESS(D2_Row,Direction)) & ": " & $S$10, "Queue Length Estimation: " & $B$102 & ": " & $S$10)))} -> Queue Length Estimation: Westbound: Norman Ave
N31: AM | Q31: OP | T31: PM | W31: EV | Z31: Total
N32: Car | O32: MCV | P32: HCV | Q32: Car | R32: MCV | S32: HCV | T32: Car | U32: MCV | V32: HCV | W32: Car | X32: MCV | Y32: HCV
B33: Dir 1 | C33: Dir 2 | M33: =$E$12 -> 2012 | N33: {=INDIRECT("'Traffic Count'!"&ADDRESS(D2_Row,Car_AM))*$A$7%} -> 706.6 | O33: {=INDIRECT("'Traffic Count'!"&ADDRESS(D2_Row,MCV_AM))*$A$7%} -> 40 | P33: {=INDIRECT("'Traffic Count'!"&ADDRESS(D2_Row,HCV_AM))*$A$7%} -> 4 | Q33: {=INDIRECT("'Traffic Count'!"&ADDRESS(D2_Row,Car_OP))*$A$7%} -> 2927.2 | R33: {=INDIRECT("'Traffic Count'!"&ADDRESS(D2_Row,MCV_OP))*$A$7%} -> 163 | S33: {=INDIRECT("'Traffic Count'!"&ADDRESS(D2_Row,HCV_OP))*$A$7%} -> 21.8 | T33: {=INDIRECT("'Traffic Count'!"&ADDRESS(D2_Row,Car_PM))*$A$7%} -> 1286.2 | U33: {=INDIRECT("'Traffic Count'!"&ADDRESS(D2_Row,MCV_PM))*$A$7%} -> 25.2 | V33: {=INDIRECT("'Traffic Count'!"&ADDRESS(D2_Row,HCV_PM))*$A$7%} -> 2.6 | W33: {=INDIRECT("'Traffic Count'!"&ADDRESS(D2_Row,Car_EV))*$A$7%} -> 2114.6 | X33: {=INDIRECT("'Traffic Count'!"&ADDRESS(D2_Row,MCV_EV))*$A$7%} -> 68 | Y33: {=INDIRECT("'Traffic Count'!"&ADDRESS(D2_Row,HCV_EV))*$A$7%} -> 14.8 | Z33: =N33+O33+P33+Q33+R33+S33+T33+U33+V33+W33+X33+Y33 -> 7374
A34: Row | B34: =MATCH(B12,'Traffic Count'!A2:A523,0)+1 -> 170 | C34: =MATCH(B13,'Traffic Count'!A2:A523,0)+1 -> 188 | L34: Estimated | M34: =$I$12 -> 2026 | N34: =ROUNDUP(N33*(1+$G$14/100)^$G$13,0) -> 999 | O34: =ROUNDUP(O33*(1+$G$14/100)^$G$13,0) -> 57 | P34: =ROUNDUP(P33*(1+$G$14/100)^$G$13,0) -> 6 | Q34: =ROUNDUP(Q33*(1+$G$14/100)^$G$13,0) -> 4137 | R34: =ROUNDUP(R33*(1+$G$14/100)^$G$13,0) -> 231 | S34: =ROUNDUP(S33*(1+$G$14/100)^$G$13,0) -> 31 | T34: =ROUNDUP(T33*(1+$G$14/100)^$G$13,0) -> 1818 | U34: =ROUNDUP(U33*(1+$G$14/100)^$G$13,0) -> 36 | ... Z34: =ROUNDUP(Z33*(1+$G$14/100)^$G$13,0) -> 10420
H35: {=INDIRECT("'Traffic Count'!"&ADDRESS(D1_Row,Car_AM))} -> 4352 | M35: Hrly Avg | N35: =ROUNDUP(N34/$J$6,0) -> 500 | O35: =ROUNDUP(O34/$J$6,0) -> 29 | P35: =ROUNDUP(P34/$J$6,0) -> 3 | Q35: =ROUNDUP(Q34/$J$7,0) -> 591 | R35: =ROUNDUP(R34/$J$7,0) -> 33 | S35: =ROUNDUP(S34/$J$7,0) -> 5 | T35: =ROUNDUP(T34/$J$8,0) -> 909 | U35: =ROUNDUP(U34/$J$8,0) -> 18 | V35: =ROUNDUP(V34/$J$8,0) -> 2 | W35: =ROUNDUP(W34/$J$9,0) -> 230 | X35: =ROUNDUP(X34/$J$9,0) -> 8 | Y35: =ROUNDUP(Y34/$J$9,0) -> 2
B36: AM | C36: OP | D36: PM | E36: EV | L36: Queue Length Estimation
A37: Car | B37: =COLUMN('Traffic Count'!L83) -> 12 | C37: =COLUMN('Traffic Count'!P83) -> 16 | D37: =COLUMN('Traffic Count'!T83) -> 20 | E37: =COLUMN('Traffic Count'!X83) -> 24 | L37: Volume | M37: per 5 mins | N37: =ROUNDUP(N35*5/60,0) -> 42 | O37: =ROUNDUP(O35*5/60,0) -> 3 | P37: =ROUNDUP(P35*5/60,0) -> 1 | Q37: =ROUNDUP(Q35*5/60,0) -> 50 | R37: =ROUNDUP(R35*5/60,0) -> 3 | S37: =ROUNDUP(S35*5/60,0) -> 1 | T37: =ROUNDUP(T35*5/60,0) -> 76 | U37: =ROUNDUP(U35*5/60,0) -> 2 | ... Y37: =ROUNDUP(Y35*5/60,0) -> 1 | Z37: Max Queue
A38: MCV | B38: =COLUMN('Traffic Count'!M84) -> 13 | C38: =COLUMN('Traffic Count'!Q84) -> 17 | D38: =COLUMN('Traffic Count'!U84) -> 21 | E38: =COLUMN('Traffic Count'!Y84) -> 25 | L38: 2 min. | M38: Length (m) | N38: =N37*$C$23+(SUM(O37:P37)*$D$23) -> 132.8 | Q38: =Q37*$C$23+(SUM(R37:S37)*$D$23) -> 152 | T38: =T37*$C$23+(SUM(U37:V37)*$D$23) -> 206.4 | W38: =W37*$C$23+(SUM(X37:Y37)*$D$23) -> 64 | Z38: =MAX(N38:Y38) -> 206.4
A39: HCV | B39: =COLUMN('Traffic Count'!N85) -> 14 | C39: =COLUMN('Traffic Count'!R85) -> 18 | D39: =COLUMN('Traffic Count'!V85) -> 22 | E39: =COLUMN('Traffic Count'!Z85) -> 26 | L39: 5 min. | M39: Length (m) | N39: =N37*$C$24+(SUM(O37:P37)*$D$24) -> 332 | Q39: =Q37*$C$24+(SUM(R37:S37)*$D$24) -> 380 | T39: =T37*$C$24+(SUM(U37:V37)*$D$24) -> 516 | W39: =W37*$C$24+(SUM(X37:Y37)*$D$24) -> 160 | Z39: =MAX(N39:Y39) -> 516
L40: 10 min. | M40: Length (m) | N40: =N37*$C$25+(SUM(O37:P37)*$D$25) -> 664 | Q40: =Q37*$C$25+(SUM(R37:S37)*$D$25) -> 760 | T40: =T37*$C$25+(SUM(U37:V37)*$D$25) -> 1032 | W40: =W37*$C$25+(SUM(X37:Y37)*$D$25) -> 320 | Z40: =MAX(N40:Y40) -> 1032
A42: Road Name | B42: =COLUMN('Traffic Count'!G2) -> 7
A43: Location | B43: =COLUMN('Traffic Count'!H3) -> 8 | L43: Road Name | N43: Norman Ave / Lamington Ave
A44: Direction | B44: =COLUMN('Traffic Count'!I4) -> 9 | L44: Direction | N44: East/West
A45: Latitude | B45: =COLUMN('Traffic Count'!J5) -> 10 | L45: Assumed percentage | N45: 5 | O45: {="% of " &INDIRECT("'Traffic Count'!"&ADDRESS(D2_Row,Road_Name)) & " at " & INDIRECT("'Traffic Count'!"&ADDRESS(D2_Row,Location)) & " assumed for " & N43} -> % of Lutwyche Rd at south of Nicolas St assumed for Norman Ave / Lamington Ave
A46: Longitude | B46: =COLUMN('Traffic Count'!K6) -> 11
...
